<?xml version="1.0"?>
<robot name="rover_arm">
  <material name="mat_silver">
    <color rgba="0.8 0.8 0.8 1"/>
  </material>

  <link name="world" />
  
  
  
  

  <link name="base_link">
    <visual>
      <origin xyz="0 0 0.07" rpy="3.1415 0 0"/>
      <geometry>
        <mesh filename="package://rover_arm/meshes/Joint1.stl" scale="1 1 1"/>
      </geometry>
      <material name="mat_silver"/>
    </visual>
    <visual>
      <origin xyz="0.02 0.017 0.23" rpy="-1.5707 0.16 0"/>
      <geometry>
        <mesh filename="package://rover_arm/meshes/Connector1.stl" scale="1 1 1"/>
      </geometry>
      <material name="mat_silver"/>
    </visual>
    <collision>
      <origin xyz="0 0 0.16" rpy="0 0 0" />
      <geometry>
        <box size="0.15 0.15 0.32" />
      </geometry>
    </collision>
    <inertial>
      <mass value="10"/>
      <inertia ixx="0.002" ixy="0.0" ixz="0.0" iyy="0.002" iyz="0.0" izz="0.0005"/>
    </inertial>
  </link>

  <link name="link1">
    <visual>
      <origin xyz="0 0 0" rpy="-1.568 -1.2 0 " />
      <geometry>
         <mesh filename="package://rover_arm/meshes/Joint2.stl" scale="1 1 1"/>
      </geometry>
      <material name="mat_silver" />
    </visual>
    <visual>
      <origin xyz="0 0.01 0.19" rpy="-1.56 0 0" />
      <geometry>
        <mesh filename="package://rover_arm/meshes/Link1.stl" scale="1 1 1"/>
      </geometry>
      <material name="mat_silver" />
    </visual>
    <visual>
      <origin xyz="0 0 0.363" rpy="1.568 0 0" />
      <geometry>
         <mesh filename="package://rover_arm/meshes/Connector2.stl" scale="1 1 1"/>
      </geometry>
      <material name="mat_silver" />
    </visual>
    <collision>
      <origin xyz="0 0 0.18" rpy="0 0 0" />
      <geometry>
       <box size="0.14 0.135 0.53" />
      </geometry>
    </collision>
    <inertial>
      <mass value="1"/>
      <inertia ixx="0.0004" ixy="0.0" ixz="0.0" iyy="0.0006" iyz="0.0" izz="0.00004"/>
    </inertial>
  </link>

  <link name="link2">
    <visual>
      <origin xyz="0.01 0.08 0.001" rpy="1.57 3.3 0.01" />
      <geometry>
        <mesh filename="package://rover_arm/meshes/Joint3.stl" scale="1 1 1"/>
     </geometry>
     <material name="mat_silver" />
    </visual>
    <visual>
      <origin xyz="0.15 0.075 0" rpy="0 0 1.56" />
      <geometry>
        <mesh filename="package://rover_arm/meshes/Link2.stl" scale="1 1 1"/>
     </geometry>
     <material name="mat_silver" />
    </visual>
    <visual>
     <origin xyz="0.255 0.07 0" rpy="1.55 -1.6 0" />
     <geometry>
        <mesh filename="package://rover_arm/meshes/Connector3.stl" scale="1 1 1"/>
     </geometry>
     <material name="mat_silver" />
    </visual>
    <collision>
      <origin xyz="0.13 0.05 0" rpy="0 0 0" />
      <geometry>
       <box size="0.385 0.14 0.15" />
     </geometry>
    </collision>
    <inertial>
     <mass value="1"/>
     <inertia ixx="0.00004" ixy="0.0" ixz="0.0" iyy="0.0003" iyz="0.0" izz="0.0003"/>
   </inertial>
  </link>

  <link name="link3">
    <visual>
        <origin xyz="0 0.001 0" rpy="0 0 0" />
        <geometry>
         <box size="0.12 0.12 0.12" />
        </geometry>
        <material name="mat_silver" />
    </visual>
    <collision>
      <origin xyz="0 0.01 0" rpy="0 0 0" />
      <geometry>
        <box size="0.12 0.12 0.12" />
      </geometry>
    </collision>
    <inertial>
      <mass value="1"/>
      <inertia ixx="0.000042" ixy="0.0" ixz="0.0" iyy="0.000042" iyz="0.0" izz="0.000042"/>
    </inertial>
  </link>

  <joint name="joint1" type="continuous">
    <parent link="world" />
    <child link="base_link" />
    <origin xyz="0 0 0" rpy="0 0 0" />
    <axis xyz="0 0 1" />
    <limit velocity="100" effort="100" />
    
  </joint>

  <joint name="joint2" type="revolute">
    <parent link="base_link" />
    <child link="link1" />
    <origin xyz="0.03 0.18 0.24" rpy="0 0 0" />
    <axis xyz="0 -1 0" />
    <limit lower="-1.5707" upper="0" velocity="100" effort="100" />
  </joint>

  <joint name="joint3" type="revolute">
    <parent link="link1" />
    <child link="link2" />
    <origin xyz="0 -0.22 0.38" rpy="0 0 0" />
    <axis xyz="0 1 0" />
    <limit lower="-1.5707" upper="1.5707" velocity="100" effort="100" />
  </joint>

  <joint name="joint4" type="revolute">
      <parent link="link2" />
      <child link="link3" />
      <origin xyz="0.25 0.2 0" rpy="0 0 0" />
      <axis xyz="0 1 0" />
      <limit lower="-1.5707" upper="1.5707" velocity="100" effort="100" />
  </joint>

  <transmission name="tran1">
    <type>transmission_interface/SimpleTransmission</type>
    <joint name="joint1">
      <hardwareInterface>hardware_interface/EffortJointInterface</hardwareInterface>
    </joint>
    <actuator name="motor1">
      <hardwareInterface>hardware_interface/EffortJointInterface</hardwareInterface>
      <mechanicalReduction>1</mechanicalReduction>
    </actuator>
  </transmission>

  <transmission name="tran2">
    <type>transmission_interface/SimpleTransmission</type>
    <joint name="joint2">
      <hardwareInterface>hardware_interface/EffortJointInterface</hardwareInterface>
    </joint>
    <actuator name="motor2">
      <hardwareInterface>hardware_interface/EffortJointInterface</hardwareInterface>
      <mechanicalReduction>1</mechanicalReduction>
    </actuator>
  </transmission>

  <transmission name="tran3">
    <type>transmission_interface/SimpleTransmission</type>
    <joint name="joint3">
      <hardwareInterface>hardware_interface/EffortJointInterface</hardwareInterface>
    </joint>
    <actuator name="motor3">
      <hardwareInterface>hardware_interface/EffortJointInterface</hardwareInterface>
      <mechanicalReduction>1</mechanicalReduction>
    </actuator>
  </transmission>

  
  <transmission name="tran4">
    <type>transmission_interface/SimpleTransmission</type>
    <joint name="joint4">
      <hardwareInterface>hardware_interface/EffortJointInterface</hardwareInterface>
    </joint>
    <actuator name="motor4">
      <hardwareInterface>hardware_interface/EffortJointInterface</hardwareInterface>
      <mechanicalReduction>1</mechanicalReduction>
    </actuator>
  </transmission>
  
  <gazebo>
    <plugin name="gazebo_ros_control" filename="libgazebo_ros_control.so">
      <robotNamespace>/</robotNamespace>
    </plugin>
  </gazebo>

  
 
</robot>
